Promises in JavaScript are a powerful tool for managing asynchronous code. They provide a cleaner and more organized way to work with code that may not have completed yet, such as network requests, file operations, or any other tasks that might take some time.

Here's how promises work:

Creation of a Promise:

A promise is created using the Promise constructor. It takes a function with two parameters: resolve and reject.

const myPromise = new Promise((resolve, reject) => {
// Asynchronous code goes here
// When the task is complete, call either resolve() or reject()
});
resolve: This function is called when the asynchronous operation is successful. It signals that the promise has fulfilled its purpose and returns a value.
reject: This function is called if an error occurs during the asynchronous operation. It signals that the promise has failed and returns an error object.
States of a Promise:

A promise can be in one of three states:

Pending: The initial state. The promise is still in progress and hasn't been fulfilled or rejected yet.
Fulfilled: The asynchronous operation was successful, and the promise is resolved with a value.
Rejected: An error occurred during the asynchronous operation, and the promise is rejected with an error.
Chaining Promises:

Promises can be chained using the .then() method, which allows you to specify what should happen when a promise is fulfilled or rejected.

```js
myPromise
  .then((result) => {
    // Handle the fulfilled state
    console.log("Promise fulfilled with result:", result);
  })
  .catch((error) => {
    // Handle the rejected state
    console.error("Promise rejected with error:", error);
  });
```

The .then() method takes two optional callback functions: one for the fulfilled state and one for the rejected state.

Handling Errors:

To handle errors in a promise chain, you can use the .catch() method. It acts as a catch-all for any errors that occur in the promise chain.

```js
myPromise
  .then((result) => {
    // Handle the fulfilled state
    console.log("Promise fulfilled with result:", result);
  })
  .catch((error) => {
    // Handle any errors that occurred in the promise chain
    console.error("An error occurred:", error);
  });
```
